Workbook

Sheet Gen 1000
A1: Name of Work | B1: Construction of various buildings of Waste Management Plant and allied structures including Civil, Electrical and Mechanical works for FRFCF at Kalpakkam
A2: TS No | B2: C-0225/CV-1 (E)/FRFCF/IGCAR/2015 dt 12.01.2015
A3: Contractor | B3: M/s. Larsen & Toubro Limited, Chennai - 600 089
A4: W.O NO | B4: IGCAR/FRFCF/CV-1(E)/ETR-025/WO/2016/213 dt. 24.02.2016
A5: Agt No. | B5: IGCAR/FRFCF/CIVIL/A.41/2016 dt. 29.02.2016
A6: RA-Bill No | B6: RA BILL No. 03 (Zone-II) CC No.7732 | C6: 1
A7: Date of Measurement | B7: Item No | C7: Description of Work | D7: Measurement Up todate | I7: Remarks
D8: No | E8: L | F8: B | G8: D | H8: Content Area

Sheet Gen 1001
A1: Name of Work | B1: Construction of various buildings of Waste Management Plant and allied structures including Civil, Electrical and Mechanical works for FRFCF at Kalpakkam
A2: TS No | B2: C-0225/CV-1 (E)/FRFCF/IGCAR/2015 dt 12.01.2015
A3: Contractor | B3: M/s. Larsen & Toubro Limited, Chennai - 600 089
A4: W.O NO | B4: IGCAR/FRFCF/CV-1(E)/ETR-025/WO/2016/213 dt. 24.02.2016
A5: Agt No. | B5: IGCAR/FRFCF/CIVIL/A.41/2016 dt. 29.02.2016
A6: RA-Bill No | B6: RA BILL No. 03 (SWB) CC No.7732 | C6: 1
A7: Date of Measurement | B7: Item No | C7: Description of Work | D7: Measurement Up todate | I7: Remarks
D8: No. | E8: L | F8: B | G8: D | H8: Content Area
A9: 01.06.16 | B9: 5.7.1 | C9: Supplying and placing insitu normal concrete N30 grade 330kg 38oC
C10: F - 2 (Grid Aa & 4) AFL -25.151 to TOC -24.75 | D10: 1 | E10: 2.2 | F10: 2.2 | G10: 0.401 | H10: =+D10*E10*F10*G10 -> 1.94084
C11: F - 5 (Grid A & 4) AFL -25.206 TOC -24.75 | D11: 1 | E11: 3.2 | F11: 3.2 | G11: 0.456 | H11: =+D11*E11*F11*G11 -> 4.66944
C12: F - 11 (Grid B & 4) AFL -25.264 to TOC -24.75 | D12: 1 | E12: 3.2 | F12: 3.2 | G12: 0.514 | H12: =+D12*E12*F12*G12 -> 5.26336
C13: F - 17 (Grid C & 4) AFL -25.044 to TOC -24.75 | D13: 1 | E13: 3.2 | F13: 3.2 | G13: 0.294 | H13: =+D13*E13*F13*G13 -> 3.01056
C14: F - 24 (Grid D & 4) AFL -24.993 to TOC -24.75 | D14: 1 | E14: 3.2 | F14: 3.2 | G14: 0.243 | H14: =+D14*E14*F14*G14 -> 2.48832
C15: TOTAL | H15: =SUM(H10:H14) -> 17.37252 | I15: Cum
D16: C/O page No: 01/MB 1002
A18: 08.06.16 | B18: 5.5 | C18: Supplying and placing insitu normal concrete N30 grade 320kg 38oC
C19: F - 29 (Grid E & 1) AFL -25.544 to TOC -24.75 | D19: 1 | E19: 3.2 | F19: 3.2 | G19: 0.794 | H19: =+D19*E19*F19*G19 -> 8.13056
C20: F - 30 (Grid E & 2) AFL -25.381 to TOC -24.75 | D20: 1 | E20: 3.2 | F20: 3.2 | G20: 0.631 | H20: =+D20*E20*F20*G20 -> 6.46144
C21: F - 32 (Grid E & 4) AFL -24.991 to TOC -24.75 | D21: 1 | E21: 3.2 | F21: 3.2 | G21: 0.241 | H21: =+D21*E21*F21*G21 -> 2.46784
C22: F - 36 (Grid F-G & 1) AFL -25.316 to TOC -24.75 | D22: 1 | E22: 9.75 | F22: 3.2 | G22: 0.566 | H22: =+D22*E22*F22*G22 -> 17.6592
C23: F - 39 (Grid F-G & 1) AFL -25.103 to TOC -24.75 | D23: 1 | E23: 3.2 | F23: 3.2 | G23: 0.353 | H23: =+D23*E23*F23*G23 -> 3.61472
C24: F - 43 (Grid G & 2) AFL -25.475 to TOC -24.75 | D24: 1 | E24: 3.2 | F24: 3.2 | G24: 0.725 | H24: =+D24*E24*F24*G24 -> 7.424
C25: F - 45 (Grid G & 4) AFL -25.254 to TOC -24.75 | D25: 1 | E25: 3.2 | F25: 3.2 | G25: 0.504 | H25: =+D25*E25*F25*G25 -> 5.16096
C26: F - 48 (Grid H & 1-2) AFL -25.080 to TOC -24.75 | D26: 1 | E26: 11.025 | F26: 3.2 | G26: 0.33 | H26: =+D26*E26*F26*G26 -> 11.6424
C27: F - 49 (Grid H & 3) AFL -25.082 to TOC -24.75 | D27: 1 | E27: 3.2 | F27: 3.2 | G27: 0.332 | H27: =+D27*E27*F27*G27 -> 3.39968
C28: TOTAL | H28: =SUM(H19:H27) -> 65.9608 | I28: Cum
D29: C/O page No: 02/TMB
A32: 11.06.16 | B32: 5.5 | C32: Supplying and placing insitu normal concrete N30 grade 320kg 38oC
C33: F - 31 (Grid E & 3) AFL -25.529 to TOC -24.75 | D33: 1 | E33: 3.2 | F33: 3.2 | G33: 0.779 | H33: =+D33*E33*F33*G33 -> 7.97696
C34: F - 37 (Grid F & 2) AFL -26.102 to TOC -24.75 | D34: 1 | E34: 3.2 | F34: 3.2 | G34: 1.352 | H34: =+D34*E34*F34*G34 -> 13.84448
C35: F - 38 (Grid F & 3) AFL -25.714 to TOC -24.75 | D35: 1 | E35: 3.2 | F35: 3.2 | G35: 0.964 | H35: =+D35*E35*F35*G35 -> 9.87136
C36: F - 44 (Grid G & 3) AFL -25.257 to TOC -24.75 | D36: 1 | E36: 3.2 | F36: 3.2 | G36: 0.507 | H36: =+D36*E36*F36*G36 -> 5.19168
C37: F - 50 (Grid H & 4) AFL -25.159 to TOC -24.75 | D37: 1 | E37: 3.2 | F37: 3.2 | G37: 0.409 | H37: =+D37*E37*F37*G37 -> 4.18816
C38: F - 53 (Grid J & 3) AFL -25.039 to TOC -24.75 | D38: 1 | E38: 3.2 | F38: 3.2 | G38: 0.289 | H38: =+D38*E38*F38*G38 -> 2.95936
C39: F - 54 (Grid J & 4) AFL -25.313 to TOC -24.75 | D39: 1 | E39: 3.2 | F39: 3.2 | G39: 0.563 | H39: =+D39*E39*F39*G39 -> 5.76512
C40: TOTAL | H40: =SUM(H33:H39) -> 49.79712 | I40: Cum
D41: C/O page No: 02/TMB
A43: 13.06.16 | B43: 5.5 | C43: Supplying and placing insitu normal concrete N30 grade 320kg 38oC
C44: F - 18 (Grid C & 5) AFL -25.096 to TOC -24.75 | D44: 1 | E44: 3.2 | F44: 3.2 | G44: 0.346 | H44: =+D44*E44*F44*G44 -> 3.54304
...

Sheet Gen 1003
A1: Name of Work | B1: Construction of various buildings of Waste Management Plant and allied structures including Civil, Electrical and Mechanical works for FRFCF at Kalpakkam
A2: TS No | B2: C-0225/CV-1 (E)/FRFCF/IGCAR/2015 dt 12.01.2015
A3: Contractor | B3: M/s. Larsen & Toubro Limited, Chennai - 600 089
A4: W.O NO | B4: IGCAR/FRFCF/CV-1(E)/ETR-025/WO/2016/213 dt. 24.02.2016
A5: Agt No. | B5: IGCAR/FRFCF/CIVIL/A.41/2016 dt. 29.02.2016
A6: RA-Bill No | B6: RA BILL No. 03 (Zone-V) CC No.7732 | C6: 1
A7: Date of Measurement | B7: Item No | C7: Description of Work | D7: Measurement Up todate | I7: Remarks
D8: No. | E8: L | F8: B | G8: D | H8: Content Area
A9: 07.06.16 | B9: 7.1.1 | C9: Formwork for normal concrete straight portion below from FFL
C10: F - 509 (Grid G to K & 37a to 40) EL(-24.75 to -23.25) | D10: 2 | E10: 16.075 | F10: - | G10: 1.5 | H10: =+D10*E10*G10 -> 48.225
C11: F - 509 (Grid G to K & 37a to 40) EL(-24.75 to -23.25) | D11: 2 | E11: 16.3 | F11: - | G11: 1.5 | H11: =+D11*E11*G11 -> 48.9
C12: TOTAL | H12: =SUM(H10:H11) -> 97.125 | I12: Sqm
D13: C/O page No: 01/MB 1002
A15: 07.06.16 | B15: 5.8.1 | C15: Supplying and placing insitu Normal concrete of N30 grade 29o c
C16: F - 509 (Grid G to K & 37a to 40) EL(-24.75 to -23.25) | D16: 1 | E16: 16.3 | F16: 16.075 | G16: 1.5 | H16: =+D16*E16*F16*G16 -> 393.03375
C17: TOTAL | H17: =SUM(H16:H16) -> 393.03375 | I17: Cum
D18: C/O page No: 01/MB 1002

Sheet Gen 1004
A1: Name of Work | B1: Construction of various buildings of Waste Management Plant and allied structures including Civil, Electrical and Mechanical works for FRFCF at Kalpakkam
A2: TS No | B2: C-0225/CV-1 (E)/FRFCF/IGCAR/2015 dt 12.01.2015
A3: Contractor | B3: M/s. Larsen & Toubro Limited, Chennai - 600 089
A4: W.O NO | B4: IGCAR/FRFCF/CV-1(E)/ETR-025/WO/2016/213 dt. 24.02.2016
A5: Agt No. | B5: IGCAR/FRFCF/CIVIL/A.41/2016 dt. 29.02.2016
A6: RA-Bill No | B6: RA BILL No. 03 (Zone-III) CC No.7605 | C6: 1
A7: Date of Measurement | B7: Item No | C7: Description of Work | D7: Measurement Up todate | I7: Remarks
D8: No. | E8: L | F8: B | G8: D | H8: Content Area

Sheet Steel 1021
A1: NAME OF WORK | C1: Construction of various buildings of Waste Management Plant and allied structures including Civil, Electrical and Mechanical works for FRFCF at Kalpakkam
A2: TS. No | C2: C-0225/CV-1 (E)/FRFCF/IGCAR/2015 dt 12.01.2015
A3: NAME OF CONTRACTOR | C3: M/s. Larsen & toubro Limited, Chennai - 600 089
A4: WORK ORDER NO | C4: IGCAR/FRFCF/CV-1(E)/ETR-025/WO/2016/213 dt. 24.02.2016
A5: AGT NO | C5: IGCAR/FRFCF/CIVIL/A.41/2016 dt. 29.02.2016
A6: RA BILL NO | C6: RA BILL NO. 03 (Zone - V) CC NO. 7732
A7: Date of Measur -ement | B7: Item No | C7: Description of Work | D7: Dia of rod [mm] | E7: Nos. | F7: Length in Metres | G7: TOTAL LENGTH | P7: Remarks
G8: 8 | H8: 10 | I8: 12 | J8: 16 | K8: 20 | L8: 25 | M8: 28 | N8: 32 | O8: 36
A9: 25.04.2016 | B9: 8 | C9: Reinforcement
C10: Footing ( F - 509 )
C11: Bottom N/S direction @150C/C | D11: 20 | E11: =54+53 -> 107 | F11: =(16.3-0.15-0.08-0.04)+((1.5-0.15)*2) -> 18.73 | G11: =IF(D11 = 8,E11*F11," -") -> - | H11: =IF(D11 = 10,E11*F11," -") -> - | I11: =IF(D11=12,E11*F11,"-") -> - | J11: =IF(D11=16,E11*F11,"-") -> - | K11: =IF(D11=20,E11*F11,"-") -> 2004.11 | L11: =IF(D11=25,E11*F11,"-") -> - | M11: =IF(D11=28,E11*F11,"-") -> - | N11: =IF(D11=32,E11*F11,"-") -> - | O11: =IF(D11=36,E11*F11,"-") -> -
C12: Bottom N/S direction laps | D12: 20 | E12: =54+53 -> 107 | F12: 0.94 | G12: =IF(D12 = 8,E12*F12," -") -> - | H12: =IF(D12 = 10,E12*F12," -") -> - | I12: =IF(D12=12,E12*F12,"-") -> - | J12: =IF(D12=16,E12*F12,"-") -> - | K12: =IF(D12=20,E12*F12,"-") -> 100.58 | L12: =IF(D12=25,E12*F12,"-") -> - | M12: =IF(D12=28,E12*F12,"-") -> - | N12: =IF(D12=32,E12*F12,"-") -> - | O12: =IF(D12=36,E12*F12,"-") -> -
C13: Bottom E/W direction @150C/C | D13: 20 | E13: 109 | F13: =(16.075-0.15-0.08-0.04)+((1.5-0.15-0.04)*2) -> 18.425 | G13: =IF(D13 = 8,E13*F13," -") -> - | H13: =IF(D13 = 10,E13*F13," -") -> - | I13: =IF(D13=12,E13*F13,"-") -> - | J13: =IF(D13=16,E13*F13,"-") -> - | K13: =IF(D13=20,E13*F13,"-") -> 2008.325 | L13: =IF(D13=25,E13*F13,"-") -> - | M13: =IF(D13=28,E13*F13,"-") -> - | N13: =IF(D13=32,E13*F13,"-") -> - | O13: =IF(D13=36,E13*F13,"-") -> -
C14: Bottom E/W direction laps | D14: 20 | E14: 109 | F14: 0.94 | G14: =IF(D14 = 8,E14*F14," -") -> - | H14: =IF(D14 = 10,E14*F14," -") -> - | I14: =IF(D14=12,E14*F14,"-") -> - | J14: =IF(D14=16,E14*F14,"-") -> - | K14: =IF(D14=20,E14*F14,"-") -> 102.46 | L14: =IF(D14=25,E14*F14,"-") -> - | M14: =IF(D14=28,E14*F14,"-") -> - | N14: =IF(D14=32,E14*F14,"-") -> - | O14: =IF(D14=36,E14*F14,"-") -> -
C15: Top E/W direction @150C/C | D15: 20 | E15: 109 | F15: =(16.075-0.15-0.08-0.04)+((1.5-0.15-0.04)*2) -> 18.425 | G15: =IF(D15 = 8,E15*F15," -") -> - | H15: =IF(D15 = 10,E15*F15," -") -> - | I15: =IF(D15=12,E15*F15,"-") -> - | J15: =IF(D15=16,E15*F15,"-") -> - | K15: =IF(D15=20,E15*F15,"-") -> 2008.325 | L15: =IF(D15=25,E15*F15,"-") -> - | M15: =IF(D15=28,E15*F15,"-") -> - | N15: =IF(D15=32,E15*F15,"-") -> - | O15: =IF(D15=36,E15*F15,"-") -> -
C16: Top E/W direction laps | D16: 20 | E16: 109 | F16: 0.94 | G16: =IF(D16 = 8,E16*F16," -") -> - | H16: =IF(D16 = 10,E16*F16," -") -> - | I16: =IF(D16=12,E16*F16,"-") -> - | J16: =IF(D16=16,E16*F16,"-") -> - | K16: =IF(D16=20,E16*F16,"-") -> 102.46 | L16: =IF(D16=25,E16*F16,"-") -> - | M16: =IF(D16=28,E16*F16,"-") -> - | N16: =IF(D16=32,E16*F16,"-") -> - | O16: =IF(D16=36,E16*F16,"-") -> -
C17: Top N/S direction @150C/C | D17: 20 | E17: =54+53 -> 107 | F17: =(16.3-0.15-0.08-0.04)+((1.5-0.15)*2) -> 18.73 | G17: =IF(D17 = 8,E17*F17," -") -> - | H17: =IF(D17 = 10,E17*F17," -") -> - | I17: =IF(D17=12,E17*F17,"-") -> - | J17: =IF(D17=16,E17*F17,"-") -> - | K17: =IF(D17=20,E17*F17,"-") -> 2004.11 | L17: =IF(D17=25,E17*F17,"-") -> - | M17: =IF(D17=28,E17*F17,"-") -> - | N17: =IF(D17=32,E17*F17,"-") -> - | O17: =IF(D17=36,E17*F17,"-") -> -
C18: Top N/S direction laps | D18: 20 | E18: =54+53 -> 107 | F18: 0.94 | G18: =IF(D18 = 8,E18*F18," -") -> - | H18: =IF(D18 = 10,E18*F18," -") -> - | I18: =IF(D18=12,E18*F18,"-") -> - | J18: =IF(D18=16,E18*F18,"-") -> - | K18: =IF(D18=20,E18*F18,"-") -> 100.58 | L18: =IF(D18=25,E18*F18,"-") -> - | M18: =IF(D18=28,E18*F18,"-") -> - | N18: =IF(D18=32,E18*F18,"-") -> - | O18: =IF(D18=36,E18*F18,"-") -> -
C19: Face Bars @ 250C/C | D19: 20 | E19: 6 | F19: =+(((16.3-0.15)*2)-0.16)+((16.075-0.15)*2) -> 63.99 | G19: =IF(D19 = 8,E19*F19," -") -> - | H19: =IF(D19 = 10,E19*F19," -") -> - | I19: =IF(D19=12,E19*F19,"-") -> - | J19: =IF(D19=16,E19*F19,"-") -> - | K19: =IF(D19=20,E19*F19,"-") -> 383.94 | L19: =IF(D19=25,E19*F19,"-") -> - | M19: =IF(D19=28,E19*F19,"-") -> - | N19: =IF(D19=32,E19*F19,"-") -> - | O19: =IF(D19=36,E19*F19,"-") -> -
C20: Lap | D20: 20 | E20: 36 | F20: 0.94 | G20: =IF(D20 = 8,E20*F20," -") -> - | H20: =IF(D20 = 10,E20*F20," -") -> - | I20: =IF(D20=12,E20*F20,"-") -> - | J20: =IF(D20=16,E20*F20,"-") -> - | K20: =IF(D20=20,E20*F20,"-") -> 33.84 | L20: =IF(D20=25,E20*F20,"-") -> - | M20: =IF(D20=28,E20*F20,"-") -> - | N20: =IF(D20=32,E20*F20,"-") -> - | O20: =IF(D20=36,E20*F20,"-") -> -
C21: Column C5035,5036,5040,5041 (4nos)
C22: Verticals upto EL-23.25 | D22: 36 | E22: =12*4 -> 48 | F22: =1.5-0.075-0.04-0.036-0.036+0.374 -> 1.687 | G22: =IF(D22 = 8,E22*F22," -") -> - | H22: =IF(D22 = 10,E22*F22," -") -> - | I22: =IF(D22=12,E22*F22,"-") -> - | J22: =IF(D22=16,E22*F22,"-") -> - | K22: =IF(D22=20,E22*F22,"-") -> - | L22: =IF(D22=25,E22*F22,"-") -> - | M22: =IF(D22=28,E22*F22,"-") -> - | N22: =IF(D22=32,E22*F22,"-") -> - | O22: =IF(D22=36,E22*F22,"-") -> 80.976
C23: Master ring @ 150C/C | D23: 10 | E23: =4*11 -> 44 | F23: =+((1-0.1-0.04)*2+((0.75-0.1)*2)+(0.1*2)) -> 3.22 | G23: =IF(D23 = 8,E23*F23," -") -> - | H23: =IF(D23 = 10,E23*F23," -") -> 141.68 | I23: =IF(D23=12,E23*F23,"-") -> - | J23: =IF(D23=16,E23*F23,"-") -> - | K23: =IF(D23=20,E23*F23,"-") -> - | L23: =IF(D23=25,E23*F23,"-") -> - | M23: =IF(D23=28,E23*F23,"-") -> - | N23: =IF(D23=32,E23*F23,"-") -> - | O23: =IF(D23=36,E23*F23,"-") -> -
C24: Internal ring @ 150C/C | D24: 10 | E24: =4*10 -> 40 | F24: =+((1-0.1-0.04)*2+(0.272*2)+0.2) -> 2.464 | G24: =IF(D24 = 8,E24*F24," -") -> - | H24: =IF(D24 = 10,E24*F24," -") -> 98.56 | I24: =IF(D24=12,E24*F24,"-") -> - | J24: =IF(D24=16,E24*F24,"-") -> - | K24: =IF(D24=20,E24*F24,"-") -> - | L24: =IF(D24=25,E24*F24,"-") -> - | M24: =IF(D24=28,E24*F24,"-") -> - | N24: =IF(D24=32,E24*F24,"-") -> - | O24: =IF(D24=36,E24*F24,"-") -> -
C25: Internal ring @ 150C/C | D25: 10 | E25: =4*10 -> 40 | F25: =+((0.75-0.1-0.04)*2+(0.356*2)+0.2) -> 2.132 | G25: =IF(D25 = 8,E25*F25," -") -> - | H25: =IF(D25 = 10,E25*F25," -") -> 85.28 | I25: =IF(D25=12,E25*F25,"-") -> - | J25: =IF(D25=16,E25*F25,"-") -> - | K25: =IF(D25=20,E25*F25,"-") -> - | L25: =IF(D25=25,E25*F25,"-") -> - | M25: =IF(D25=28,E25*F25,"-") -> - | N25: =IF(D25=32,E25*F25,"-") -> - | O25: =IF(D25=36,E25*F25,"-") -> -
C26: Column C5037,5042 (2nos)
C27: Verticals upto EL-23.25 | D27: 36 | E27: =28*2 -> 56 | F27: =1.5-0.075-0.04-0.036-0.036+0.374 -> 1.687 | G27: =IF(D27 = 8,E27*F27," -") -> - | H27: =IF(D27 = 10,E27*F27," -") -> - | I27: =IF(D27=12,E27*F27,"-") -> - | J27: =IF(D27=16,E27*F27,"-") -> - | K27: =IF(D27=20,E27*F27,"-") -> - | L27: =IF(D27=25,E27*F27,"-") -> - | M27: =IF(D27=28,E27*F27,"-") -> - | N27: =IF(D27=32,E27*F27,"-") -> - | O27: =IF(D27=36,E27*F27,"-") -> 94.472
C28: Master ring @ 125C/C | D28: 10 | E28: =13*2 -> 26 | F28: =+((1-0.1-0.04)*2+((0.75-0.1-0.035)*2)+(0.1*2)) -> 3.15 | G28: =IF(D28 = 8,E28*F28," -") -> - | H28: =IF(D28 = 10,E28*F28," -") -> 81.9 | I28: =IF(D28=12,E28*F28,"-") -> - | J28: =IF(D28=16,E28*F28,"-") -> - | K28: =IF(D28=20,E28*F28,"-") -> - | L28: =IF(D28=25,E28*F28,"-") -> - | M28: =IF(D28=28,E28*F28,"-") -> - | N28: =IF(D28=32,E28*F28,"-") -> - | O28: =IF(D28=36,E28*F28,"-") -> -
C29: Internal ring @ 125C/C | D29: 10 | E29: =2*12*2 -> 48 | F29: =+((1-0.1-0.04)*2+(0.164*2)+0.2) -> 2.248 | G29: =IF(D29 = 8,E29*F29," -") -> - | H29: =IF(D29 = 10,E29*F29," -") -> 107.904 | I29: =IF(D29=12,E29*F29,"-") -> - | J29: =IF(D29=16,E29*F29,"-") -> - | K29: =IF(D29=20,E29*F29,"-") -> - | L29: =IF(D29=25,E29*F29,"-") -> - | M29: =IF(D29=28,E29*F29,"-") -> - | N29: =IF(D29=32,E29*F29,"-") -> - | O29: =IF(D29=36,E29*F29,"-") -> -
C30: Internal links @ 125C/C | D30: 10 | E30: 12 | F30: =0.9+0.1+0.1 -> 1.1 | G30: =IF(D30 = 8,E30*F30," -") -> - | H30: =IF(D30 = 10,E30*F30," -") -> 13.2 | I30: =IF(D30=12,E30*F30,"-") -> - | J30: =IF(D30=16,E30*F30,"-") -> - | K30: =IF(D30=20,E30*F30,"-") -> - | L30: =IF(D30=25,E30*F30,"-") -> - | M30: =IF(D30=28,E30*F30,"-") -> - | N30: =IF(D30=32,E30*F30,"-") -> - | O30: =IF(D30=36,E30*F30,"-") -> -
C31: Internal ring @ 125C/C | D31: 10 | E31: =2*12*2 -> 48 | F31: =+((0.75-0.1-0.04-0.035)*2+(0.206*2)+0.2) -> 1.762 | G31: =IF(D31 = 8,E31*F31," -") -> - | H31: =IF(D31 = 10,E31*F31," -") -> 84.576 | I31: =IF(D31=12,E31*F31,"-") -> - | J31: =IF(D31=16,E31*F31,"-") -> - | K31: =IF(D31=20,E31*F31,"-") -> - | L31: =IF(D31=25,E31*F31,"-") -> - | M31: =IF(D31=28,E31*F31,"-") -> - | N31: =IF(D31=32,E31*F31,"-") -> - | O31: =IF(D31=36,E31*F31,"-") -> -
C32: Internal links @ 125C/C | D32: 10 | E32: 12 | F32: =0.65+0.1+0.1-0.035 -> 0.815 | G32: =IF(D32 = 8,E32*F32," -") -> - | H32: =IF(D32 = 10,E32*F32," -") -> 9.78 | I32: =IF(D32=12,E32*F32,"-") -> - | J32: =IF(D32=16,E32*F32,"-") -> - | K32: =IF(D32=20,E32*F32,"-") -> - | L32: =IF(D32=25,E32*F32,"-") -> - | M32: =IF(D32=28,E32*F32,"-") -> - | N32: =IF(D32=32,E32*F32,"-") -> - | O32: =IF(D32=36,E32*F32,"-") -> -
C33: Column C5047
C34: Verticals upto EL-23.25 | D34: 36 | E34: =28 -> 28 | F34: =1.5-0.075-0.04-0.036-0.036+0.374 -> 1.687 | G34: =IF(D34 = 8,E34*F34," -") -> - | H34: =IF(D34 = 10,E34*F34," -") -> - | I34: =IF(D34=12,E34*F34,"-") -> - | J34: =IF(D34=16,E34*F34,"-") -> - | K34: =IF(D34=20,E34*F34,"-") -> - | L34: =IF(D34=25,E34*F34,"-") -> - | M34: =IF(D34=28,E34*F34,"-") -> - | N34: =IF(D34=32,E34*F34,"-") -> - | O34: =IF(D34=36,E34*F34,"-") -> 47.236
C35: Master ring @ 100C/C | D35: 10 | E35: =15 -> 15 | F35: =+((1-0.1-0.04)*2+((1-0.1-0.035)*2)+(0.1*2)) -> 3.65 | G35: =IF(D35 = 8,E35*F35," -") -> - | H35: =IF(D35 = 10,E35*F35," -") -> 54.75 | I35: =IF(D35=12,E35*F35,"-") -> - | J35: =IF(D35=16,E35*F35,"-") -> - | K35: =IF(D35=20,E35*F35,"-") -> - | L35: =IF(D35=25,E35*F35,"-") -> - | M35: =IF(D35=28,E35*F35,"-") -> - | N35: =IF(D35=32,E35*F35,"-") -> - | O35: =IF(D35=36,E35*F35,"-") -> -
C36: Internal ring @ 100C/C | D36: 10 | E36: =14*3 -> 42 | F36: =+((1-0.1-0.04)*2+(0.182*2)+0.2) -> 2.284 | G36: =IF(D36 = 8,E36*F36," -") -> - | H36: =IF(D36 = 10,E36*F36," -") -> 95.928 | I36: =IF(D36=12,E36*F36,"-") -> - | J36: =IF(D36=16,E36*F36,"-") -> - | K36: =IF(D36=20,E36*F36,"-") -> - | L36: =IF(D36=25,E36*F36,"-") -> - | M36: =IF(D36=28,E36*F36,"-") -> - | N36: =IF(D36=32,E36*F36,"-") -> - | O36: =IF(D36=36,E36*F36,"-") -> -
C37: Internal ring @ 100C/C | D37: 10 | E37: =14*3 -> 42 | F37: =+((1-0.1-0.04-0.035)*2+(0.182*2)+0.2) -> 2.214 | G37: =IF(D37 = 8,E37*F37," -") -> - | H37: =IF(D37 = 10,E37*F37," -") -> 92.988 | I37: =IF(D37=12,E37*F37,"-") -> - | J37: =IF(D37=16,E37*F37,"-") -> - | K37: =IF(D37=20,E37*F37,"-") -> - | L37: =IF(D37=25,E37*F37,"-") -> - | M37: =IF(D37=28,E37*F37,"-") -> - | N37: =IF(D37=32,E37*F37,"-") -> - | O37: =IF(D37=36,E37*F37,"-") -> -
C38: Column C5046
C39: Verticals upto EL-23.25 | D39: 36 | E39: 20 | F39: =1.5-0.075-0.04-0.036-0.036+0.374 -> 1.687 | G39: =IF(D39 = 8,E39*F39," -") -> - | H39: =IF(D39 = 10,E39*F39," -") -> - | I39: =IF(D39=12,E39*F39,"-") -> - | J39: =IF(D39=16,E39*F39,"-") -> - | K39: =IF(D39=20,E39*F39,"-") -> - | L39: =IF(D39=25,E39*F39,"-") -> - | M39: =IF(D39=28,E39*F39,"-") -> - | N39: =IF(D39=32,E39*F39,"-") -> - | O39: =IF(D39=36,E39*F39,"-") -> 33.74
C40: Master ring @ 100C/C | D40: 10 | E40: =15 -> 15 | F40: =+((1-0.1-0.04)*2+((0.75-0.1)*2)+(0.1*2)) -> 3.22 | G40: =IF(D40 = 8,E40*F40," -") -> - | H40: =IF(D40 = 10,E40*F40," -") -> 48.3 | I40: =IF(D40=12,E40*F40,"-") -> - | J40: =IF(D40=16,E40*F40,"-") -> - | K40: =IF(D40=20,E40*F40,"-") -> - | L40: =IF(D40=25,E40*F40,"-") -> - | M40: =IF(D40=28,E40*F40,"-") -> - | N40: =IF(D40=32,E40*F40,"-") -> - | O40: =IF(D40=36,E40*F40,"-") -> -
...

Sheet Steel 1022
A1: NAME OF WORK | C1: Construction of various buildings of Waste Management Plant and allied structures including Civil, Electrical and Mechanical works for FRFCF at Kalpakkam
A2: TS. No | C2: C-0225/CV-1 (E)/FRFCF/IGCAR/2015 dt 12.01.2015
A3: NAME OF CONTRACTOR | C3: M/s. Larsen & toubro Limited, Chennai - 600 089
A4: WORK ORDER NO | C4: IGCAR/FRFCF/CV-1(E)/ETR-025/WO/2016/213 dt. 24.02.2016
A5: AGGREEMENT NO | C5: IGCAR/FRFCF/CIVIL/A.41/2016 dt. 29.02.2016
A6: RA BILL NO | C6: RA BILL NO. 03 ( SWB ) CC NO. 7605
A7: Date of Measur -ement | B7: Item No | C7: Description of Work | D7: Dia of rod [mm] | E7: Nos. | F7: Length in Metres | G7: TOTAL LENGTH | P7: Remarks
G8: 8 | H8: 10 | I8: 12 | J8: 16 | K8: 20 | L8: 25 | M8: 28 | N8: 32 | O8: 36
A9: 25.04.2016 | B9: 8 | C9: Reinforcement
C10: Footing ( F - 16,17,23,24 ) = 4nos
C11: Bottom N/S direction @150C/C | D11: 20 | E11: =20*4 -> 80 | F11: =+(3-0.15-0.08)+((1.5-0.15)*2) -> 5.47 | G11: =IF(D11 = 8,E11*F11," -") -> - | H11: =IF(D11 = 10,E11*F11," -") -> - | I11: =IF(D11=12,E11*F11,"-") -> - | J11: =IF(D11=16,E11*F11,"-") -> - | K11: =IF(D11=20,E11*F11,"-") -> 437.6 | L11: =IF(D11=25,E11*F11,"-") -> - | M11: =IF(D11=28,E11*F11,"-") -> - | N11: =IF(D11=32,E11*F11,"-") -> - | O11: =IF(D11=36,E11*F11,"-") -> -
C12: Bottom E/W direction @150C/C | D12: 20 | E12: =20*4 -> 80 | F12: =+(3-0.15-0.08)+((1.5-0.15-0.04)*2) -> 5.39 | G12: =IF(D12 = 8,E12*F12," -") -> - | H12: =IF(D12 = 10,E12*F12," -") -> - | I12: =IF(D12=12,E12*F12,"-") -> - | J12: =IF(D12=16,E12*F12,"-") -> - | K12: =IF(D12=20,E12*F12,"-") -> 431.2 | L12: =IF(D12=25,E12*F12,"-") -> - | M12: =IF(D12=28,E12*F12,"-") -> - | N12: =IF(D12=32,E12*F12,"-") -> - | O12: =IF(D12=36,E12*F12,"-") -> -
C13: Face Bars @ 250C/C | D13: 20 | E13: =6*4 -> 24 | F13: =+(3-0.15-0.04)*4 -> 11.24 | G13: =IF(D13 = 8,E13*F13," -") -> - | H13: =IF(D13 = 10,E13*F13," -") -> - | I13: =IF(D13=12,E13*F13,"-") -> - | J13: =IF(D13=16,E13*F13,"-") -> - | K13: =IF(D13=20,E13*F13,"-") -> 269.76 | L13: =IF(D13=25,E13*F13,"-") -> - | M13: =IF(D13=28,E13*F13,"-") -> - | N13: =IF(D13=32,E13*F13,"-") -> - | O13: =IF(D13=36,E13*F13,"-") -> -
C14: Lap | D14: 20 | E14: =12*4 -> 48 | F14: 0.94 | G14: =IF(D14 = 8,E14*F14," -") -> - | H14: =IF(D14 = 10,E14*F14," -") -> - | I14: =IF(D14=12,E14*F14,"-") -> - | J14: =IF(D14=16,E14*F14,"-") -> - | K14: =IF(D14=20,E14*F14,"-") -> 45.12 | L14: =IF(D14=25,E14*F14,"-") -> - | M14: =IF(D14=28,E14*F14,"-") -> - | N14: =IF(D14=32,E14*F14,"-") -> - | O14: =IF(D14=36,E14*F14,"-") -> -
C15: Top mat E/W direction @150C/C | D15: 20 | E15: =20*4 -> 80 | F15: =+(3-0.15-0.08)+((1.5-0.15-0.04)*2) -> 5.39 | G15: =IF(D15 = 8,E15*F15," -") -> - | H15: =IF(D15 = 10,E15*F15," -") -> - | I15: =IF(D15=12,E15*F15,"-") -> - | J15: =IF(D15=16,E15*F15,"-") -> - | K15: =IF(D15=20,E15*F15,"-") -> 431.2 | L15: =IF(D15=25,E15*F15,"-") -> - | M15: =IF(D15=28,E15*F15,"-") -> - | N15: =IF(D15=32,E15*F15,"-") -> - | O15: =IF(D15=36,E15*F15,"-") -> -
C16: Top mat N/S direction @150C/C | D16: 20 | E16: =20*4 -> 80 | F16: =+(3-0.15-0.08)+((1.5-0.15)*2) -> 5.47 | G16: =IF(D16 = 8,E16*F16," -") -> - | H16: =IF(D16 = 10,E16*F16," -") -> - | I16: =IF(D16=12,E16*F16,"-") -> - | J16: =IF(D16=16,E16*F16,"-") -> - | K16: =IF(D16=20,E16*F16,"-") -> 437.6 | L16: =IF(D16=25,E16*F16,"-") -> - | M16: =IF(D16=28,E16*F16,"-") -> - | N16: =IF(D16=32,E16*F16,"-") -> - | O16: =IF(D16=36,E16*F16,"-") -> -
C17: Column C120,121,130,131=4nos
C18: Verticals upto EL-23.25 | D18: 36 | E18: =16*4 -> 64 | F18: =1.5-0.075-0.04-0.036-0.036+0.374 -> 1.687 | G18: =IF(D18 = 8,E18*F18," -") -> - | H18: =IF(D18 = 10,E18*F18," -") -> - | I18: =IF(D18=12,E18*F18,"-") -> - | J18: =IF(D18=16,E18*F18,"-") -> - | K18: =IF(D18=20,E18*F18,"-") -> - | L18: =IF(D18=25,E18*F18,"-") -> - | M18: =IF(D18=28,E18*F18,"-") -> - | N18: =IF(D18=32,E18*F18,"-") -> - | O18: =IF(D18=36,E18*F18,"-") -> 107.968
C19: Master ring @ 100C/C | D19: 10 | E19: =4*15 -> 60 | F19: =+((1-0.1-0.04)*2+((0.75-0.1)*2)+(0.1*2)) -> 3.22 | G19: =IF(D19 = 8,E19*F19," -") -> - | H19: =IF(D19 = 10,E19*F19," -") -> 193.2 | I19: =IF(D19=12,E19*F19,"-") -> - | J19: =IF(D19=16,E19*F19,"-") -> - | K19: =IF(D19=20,E19*F19,"-") -> - | L19: =IF(D19=25,E19*F19,"-") -> - | M19: =IF(D19=28,E19*F19,"-") -> - | N19: =IF(D19=32,E19*F19,"-") -> - | O19: =IF(D19=36,E19*F19,"-") -> -
C20: Internal ring @ 100C/C | D20: 10 | E20: =14*2*4 -> 112 | F20: =+((1-0.1-0.04)*2+(0.281*2)+0.2) -> 2.482 | G20: =IF(D20 = 8,E20*F20," -") -> - | H20: =IF(D20 = 10,E20*F20," -") -> 277.984 | I20: =IF(D20=12,E20*F20,"-") -> - | J20: =IF(D20=16,E20*F20,"-") -> - | K20: =IF(D20=20,E20*F20,"-") -> - | L20: =IF(D20=25,E20*F20,"-") -> - | M20: =IF(D20=28,E20*F20,"-") -> - | N20: =IF(D20=32,E20*F20,"-") -> - | O20: =IF(D20=36,E20*F20,"-") -> -
C21: Internal links @ 100C/C | D21: 10 | E21: =14*2*4 -> 112 | F21: =0.9+0.1+0.1 -> 1.1 | G21: =IF(D21 = 8,E21*F21," -") -> - | H21: =IF(D21 = 10,E21*F21," -") -> 123.2 | I21: =IF(D21=12,E21*F21,"-") -> - | J21: =IF(D21=16,E21*F21,"-") -> - | K21: =IF(D21=20,E21*F21,"-") -> - | L21: =IF(D21=25,E21*F21,"-") -> - | M21: =IF(D21=28,E21*F21,"-") -> - | N21: =IF(D21=32,E21*F21,"-") -> - | O21: =IF(D21=36,E21*F21,"-") -> -
C22: Chairs | D22: 25 | E22: =6*4 -> 24 | F22: 4.18 | G22: =IF(D22 = 8,E22*F22," -") -> - | H22: =IF(D22 = 10,E22*F22," -") -> - | I22: =IF(D22=12,E22*F22,"-") -> - | J22: =IF(D22=16,E22*F22,"-") -> - | K22: =IF(D22=20,E22*F22,"-") -> - | L22: =IF(D22=25,E22*F22,"-") -> 100.32 | M22: =IF(D22=28,E22*F22,"-") -> - | N22: =IF(D22=32,E22*F22,"-") -> - | O22: =IF(D22=36,E22*F22,"-") -> -
G23: =SUM(G11:G22) -> 0 | H23: =SUM(H11:H22) -> 594.384 | I23: =SUM(I11:I22) -> 0 | J23: =SUM(J11:J22) -> 0 | K23: =SUM(K11:K22) -> 2052.48 | L23: =SUM(L11:L22) -> 100.32 | M23: =SUM(M11:M22) -> 0 | N23: =SUM(N11:N22) -> 0 | O23: =SUM(O11:O22) -> 107.968
C25: Unit Weight | G25: 0.395 | H25: 0.617 | I25: 0.888 | J25: 1.578 | K25: 2.466 | L25: 3.853 | M25: 4.834 | N25: 6.313 | O25: 7.99
C26: Total Weight | G26: =ROUND(G25*G23,3) -> 0 | H26: =ROUND(H25*H23,3) -> 366.735 | I26: =ROUND(I25*I23,3) -> 0 | J26: =ROUND(J25*J23,3) -> 0 | K26: =ROUND(K25*K23,3) -> 5061.416 | L26: =ROUND(L25*L23,3) -> 386.533 | M26: =ROUND(M25*M23,3) -> 0 | N26: =ROUND(N25*N23,3) -> 0 | O26: =ROUND(O25*O23,3) -> 862.664
B27: 8.1.1 | C27: Reinforcement - from foundation to unfinished floor level & Dia of Bars 20 mm & below | F27: =SUM(G26:K26) -> 5428.151 | G27: Kg
G28: =F27/1000 -> 5.428151 | H28: MT | I28: C/O to P-1 of 1002
B29: 8.1.2 | C29: Reinforcement - from foundation to unfinished floor level & Dia of Bars above 20 mm | F29: =SUM(L26:O26) -> 1249.197 | G29: Kg
G30: =F29/1000 -> 1.249197 | H30: MT | I30: C/O to P-1 of 1002

Sheet SA Gen 1002
A1: Name of Work | B1: Construction of various buildings of Waste Management Plant and allied structures including Civil, Electrical and Mechanical works for FRFCF at Kalpakkam
A2: TS No | B2: C-0225/CV-1 (E)/FRFCF/IGCAR/2015 dt 12.01.2015
A3: Contractor | B3: M/s. Larsen & toubro Limited, Chennai - 600 089
A4: W.O NO | B4: IGCAR/FRFCF/CV-1(E)/ETR-025/WO/2016/213 dt. 24.02.2016
A5: Agt No. | B5: IGCAR/FRFCF/CIVIL/A.41/2016 dt. 29.02.2016
A6: RA-Bill No | B6: RA BILL No. 03 (SUB ABSTRACT) CC No.7732 | C6: 1
A7: Date of Measurement | B7: Item No | C7: Description of Work | D7: Measurement Up todate | I7: Remarks
D8: No. | E8: L | F8: B | G8: D | H8: Content Area
B9: 5.5 | C9: Supplying and placing insitu normal concrete N30 grade 320kg 38oC
C10: B/F ( SWB) MB 1001 page no 3 | H10: =+'Gen 1001'!H63 -> 122.83376
C11: TOTAL | H11: =SUM(H10) -> 122.83376 | I11: Sqm
D12: C/O page No: 01/MB 1042.
B14: 5.7.1 | C14: Supplying and placing insitu normal concrete N3o 330kg 38o C temperature
C15: B/F ( SWB) MB 1001 page no 1 | H15: =+'Gen 1001'!H15 -> 17.37252
C16: B/F ( Zone -III) MB 1004 page no 1
C17: TOTAL | H17: =SUM(H15:H16) -> 17.37252 | I17: Sqm
D18: C/O page No: 01/MB 1042.
B20: 7.1.1 | C20: Form work in Straight portions for Below from FFL
C21: B/F ( SWB) MB 1001 page no 2 | H21: =+'Gen 1001'!H51 -> 72
C22: B/F ( Zone -V) MB 1003 page no 1 | H22: =+'Gen 1003'!H12 -> 97.125
C23: TOTAL | H23: =SUM(H21:H22) -> 169.125 | I23: Sqm
D24: C/O page No: 01/MB 1042.
B26: 5.8.1 | C26: Supplying and placing insitu Normal concrete of N30 grade for 29o C
C27: B/F ( SWB) MB 1001 page no 2 | H27: =+'Gen 1001'!H56 -> 54
C28: B/F ( Zone -V) MB 1003 page no 1 | H28: =+'Gen 1003'!H17 -> 393.03375
C29: TOTAL | H29: =SUM(H27:H28) -> 447.03375 | I29: Sqm
D30: C/O page No: 01/MB 1042.
B32: 8.1.1 | C32: Reinforcement - from foundation to unfinished floor level & Dia of Bars 20 mm & below
C33: B/F ( Zone- V) MB 1021 page no 2 | H33: =+'Steel 1021'!G62 -> 22.564364
C34: B/F ( SWB) MB 1022 page no 1 | H34: =+'Steel 1022'!G28 -> 5.428151
C35: TOTAL | H35: =SUM(H33:H34) -> 27.992515 | I35: MT
D36: C/O page No: 01/MB 1042.
B38: 8.1.2 | C38: Reinforcement - from foundation to unfinished floor level & Dia of Bars above 20 mm
C39: B/F ( Zone- V) MB 1021 page no 2 | H39: =+'Steel 1021'!G64 -> 7.602059
C40: B/F ( SWB) MB 1022 page no 1 | H40: =+'Steel 1022'!G30 -> 1.249197
C41: TOTAL | H41: =SUM(H39:H40) -> 8.851256 | I41: MT
D42: C/O page No: 01/MB 1042.

Sheet Abs 1042
A1: Name of work: | B1: Construction of various buildings of Waste Management Plant and allied structures including Civil, Electrical and Mechanical works for FRFCF at Kalpakkam | F1: Name of the contractor | G1: M/s. Larsen & toubro Limited, Chennai - 600 089
A2: TS NO | B2: C-0225/CV-1 (E)/FRFCF/IGCAR/2015 dt 12.01.2015 | F2: Agreement No. | G2: IGCAR/FRFCF/CIVIL/A.41/2016 dt. 29.02.2016
A3: WO.NO | B3: IGCAR/FRFCF/CV-1(E)/ETR-025/WO/2016/213 dt. 24.02.2016 | F3: Running Account bill No. | G3: RA Bill NO : 03 CC NO 7732
A4: Abstract for Month of APR - MAY 2016
A5: Item No | B5: Description of work | C5: Contents or Area | D5: Rate | E5: Per | F5: Total value to Date | G5: Deduct previous Measurements | J5: Since Last Measurement | L5: Remarks
G6: Page | H6: Quantity | I6: Amount | J6: Quantity | K6: Value
D7: Rs. P. | F7: Rs. P. | I7: Rs. P. | K7: Rs. P.
A8: 5.5 | B8: Supplying and placing insitu normal concrete N30 grade 320kg 38oC
B9: Qty Vide P1/ MB 1002 | C9: =+'SA Gen 1002'!H11 -> 122.83376 | D9: 7867 | E9: Cum | F9: =+C9*D9 -> 966333.19 | J9: =C9-H9 -> 122.83376 | K9: =F9-I9 -> 966333.19
A10: 5.7.1 | B10: Supplying and placing insitu normal concrete N30 grade with minimum cement content 330kg
B11: Qty Vide P1/ MB 1002 | C11: =+'SA Gen 1002'!H17 -> 17.37252 | D11: 7956 | E11: Cum | F11: =C11*D11 -> 138215.77 | J11: =C11-H11 -> 17.37252 | K11: =F11-I11 -> 138215.77
B12: Total
A13: 7.1.1 | B13: Designing, supplying, fabricating,erecting and fixing in position at all levels, form work for…
B14: Qty Vide P1/ MB 1002 | C14: =+'SA Gen 1002'!H23 -> 169.125 | D14: 890 | E14: Sqm | F14: =C14*D14 -> 150521.25 | J14: =C14-H14 -> 169.125 | K14: =F14-I14 -> 150521.25
B15: Total
A16: 5.8.1 | B16: Supplying and placing insitu Normal concrete of N30 grade with minimum cement content
B17: Qty Vide P1/ MB 1002 | C17: =+'SA Gen 1002'!H29 -> 447.03375 | D17: 7956 | E17: Cum | F17: =C17*D17 -> 3556600.5 | J17: =C17-H17 -> 447.03375 | K17: =F17-I17 -> 3556600.5
B18: Total
A19: 8.1.1 | B19: Reinforcement - from foundation to unfinished floor level & Dia of Bars 20 mm & below
B20: Qty Vide P1/ MB 1002 | C20: =+'SA Gen 1002'!H35 -> 27.992515 | D20: 73227 | E20: MT | F20: =C20*D20 -> 2049807.9 | J20: =C20-H20 -> 27.992515 | K20: =F20-I20 -> 2049807.9
A21: 8.1.2 | B21: Reinforcement - from foundation to unfinished floor level & Dia of Bars above 20 mm
B22: Qty Vide P1/ MB 1002 | C22: =+'SA Gen 1002'!H41 -> 8.851256 | D22: 73063 | E22: MT | F22: =C22*D22 -> 646699.32 | J22: =C22-H22 -> 8.851256 | K22: =F22-I22 -> 646699.32
B24: TOTAL COST (Rs.) | F24: =F20+F17+F14+F11+F9+F22 -> 7508177.9 | K24: =K20+K17+K14+K11+K9+K22 -> 7508177.9
B25: Less Overall Rebate = 0.0% | F25: 0 | K25: 0
B26: Secured Advance | F26: =+'Secured Advance-1042'!K19 -> 0 | K26: =F26-I26 -> 0
B27: Gross Amount (Rs.) | F27: =+F24-F25+F26 -> 7508177.9 | K27: =+K24-K25+K26 -> 7508177.9
B29: Abstract of recoveries
B31: Water Bill no: 01 | F31: Nil
B32: Total Abstract of Recovery:- | F32: =F31 -> Nil
B33: Memo of Payment
B34: Uptodate value of bill: | F34: =F24 -> 7508177.9
B35: Deduct Previous Bill Value: | F35: =I27 -> 0
B36: Deduct Abstract of Recoveries: | F36: =F32 -> Nil
B37: Balance amount to be paid in this bill:- | F37: =F34 -> 7508177.9
B39: (Amount: )

Sheet Secured Advance-1042
A1: FORM 26 A
A2: ACCOUNT OF SECURED ADVANCES
A3: (Referred to in paragraphs 10.2.14)
A4: (To be annexed to Form 26 where necessary)
B5: Division : FRFCF | J5: Name of work: Construction of various buildings of waste management plant and allied structture including civil, Electrical………
B6: Name of Contractor :- M/s.Lasern & Toubro ltd
B7: Cash Book Voucher No. …………………. Dated:-
B9: S.No. of the Bill to which the Account pertains to: RAB - 02 | J9: Reference to Agreement : IGCAR/FRFCF/CIVIL/A.41/2016 dt. 29.02.2016
J10: Name of Building:- | L10: CV-1 (E)
B11: Civil Secured Advance -1 | G11: Account of Secured Advance allowed on the Security of Materials Brought to Site
A12: Sl NO | B12: Item No | C12: Quantity Outstanding from previous bill | D12: Deduct Quantity utilized in work measrued since previous bill | E12: ADD | F12: outstanding including quantity brought to site since previous bill | G12: Full rate assesssedd by the Divisional officer | H12: Description of Item | J12: Unit | K12: Reduced rate at which rate is made | L12: Uptodate amount of advance | M12: Reference to Divisional officers written orders authorising the advance | N12: Reason for non clearance of adcance when outstanding more than three months
C13: 1 | D13: 2 | F13: 3 | G13: 4 | H13: 5 | J13: 6 | K13: 7 | L13: 8 | M13: 9 | N13: 10
A14: 1
A15: =+A14+1 -> 2
H16: Total amount | L16: =SUM(L14:L15) -> 0
B17: Total amount outstanding as per this account …………………. (C) ………………. | K17: =L16 -> 0
B18: Deduct – Amount outstanding as per entry (C) of Annexure to the previous bill …………………… | K18: 0
B19: Net amount since previous bill (in words) Rupees…………………………………………..(E) | K19: =K17-K18 -> 0 | L19: C/O to p-3 1042
H20: Three Crores Seventy One Lakhs Sixty Three Thousands Six Hundred and Fifty Six Only/-
B21: Certified (1) that the plus quantities of materials shown in column 3 of the Account above have actually been brought by the Contractor to the site of the work and the contractor had not previously received any advance on their security (2) that these materials are of an imperishable nature and all are required by the Contractor for use on the work in connection with the items for which rates for finished work have been agreed upon, and (3) that a formal agreement in Form 31 signed and executed by the Contractor in accordance with Paragraphs 10.2.24 (a) of the Central Public Works Account Code in the Divisional Office.
A25: Dated signature of Contractor | G25: Dated signature of Officer preparing the bill (Rank) | J25: ` | K25: Dated signature of Officer authorizing payment (Rank)

Sheet Steel cons
A1: NAME OF WORK | C1: Construction of various buildings of Waste Management Plant and allied structures including Civil, Electrical and Mechanical works for FRFCF at Kalpakkam
A2: TS. No | C2: C-0225/CV-1 (E)/FRFCF/IGCAR/2015 dt 12.01.2015
A3: NAME OF CONTRACTOR | C3: M/s. Larsen & toubro Limited, Chennai - 600 089
A4: WORK ORDER NO | C4: IGCAR/FRFCF/CV-1(E)/ETR-025/WO/2016/213 dt. 24.02.2016
A5: AGT NO | C5: IGCAR/FRFCF/CIVIL/A.41/2016 dt. 29.02.2016
A6: RA BILL NO | C6: RA BILL NO. 03 CC NO. 7732
O87: =SUM(F87:N87) -> 0
